Workbook
Name ReviewData: レビューデータサマリ!$F$15:$F$48
Name 原因区分: レビューデータサマリ!$D$33:$D$41
Name 実施フェーズ: レビューデータサマリ!$C$5:$C$12
Name 分類: 使用方法!$N$48:$N$52
Name 役割: 使用方法!$N$26:$N$35

Sheet 使用方法
Q1: 標準ID：DM-010 Ver8.4
B2: 使用方法
C4: 本書式は、プロジェクト計画書などのプロジェクト管理系の成果物や、要件定義書や外部設計書などのエンジニアリング系の成果物など
C5: あらゆる作業成果物のレビューに幅広く使用されることを想定している。
C7: ■ | D7: シート構成
D8: ・ | E8: レビュー実施記録 | M8: レビューの予定／実績の管理および、指摘事項の記録と対応状況を追跡する。
D9: ・ | E9: レビュー観点 | M9: 成果物作成時／レビュー時の観点（チェック項目の内容は、プロジェクトの特性に合わせて適宜修正する）。
M10: なお、本シートは参考利用の位置づけのものである。
D11: ・ | E11: レビューデータサマリ | M11: レビュー状況分析表にて収集、分析するためのデータ（記入項目は無し）。
C13: ■ | D13: レビュー実施記録の記入方法および注意点
D14: ※特に注意が必要な記入項目について、以下に説明する。
D15: 項目 | M15: 記入方法 | Q15: 注意点・補足情報
D16: 【基本情報】
D17: 横展開調査欄の使用有無 | M17: 横展開調査欄（Ｖ列移行）を使用するかをリストより選択する。 ・使用する ・使用しない | Q17: ・デフォルトでは「使用しない」が選択された状態としている。必要に応じ「使用する」に変更すること。 ・「使用する」を選択した場合は、レビュー実施記録のクローズ条件が、レビュー指摘/横展開調査全てが完了した場合に変更となる。
D18: 実施フェーズ | M18: リストから選択する。 ・提案 ・要件定義 ・外部設計 ・内部設計 ・プログラム開発 ・結合テスト（ITa） ・結合テスト（ITb） ・システムテスト | Q18: 結合テストをITa、ITbに分割していない場合は、結合テスト（ITa）を選択する。
D19: レビューID | M19: 各プロジェクトが、以下 「レビューID」採番ルールで定義した割り当て方法で、レビューを個別に識別できるIDを設定し、記入する。 ■「レビューID」採番ルール ・レビューを実施する際、レビュー1回ごとに、レビューを個別に識別できるIDを設定して管理する。 ・計画のどのレビューに該当するかを明確にするため、次のパターンに則って割り当てる。 「レビューID」は、レビュー実施記録のファイル名設定などに使用する。 【パターン】 ① - ② - ③ - ④ ∟①： フェーズ略称 ∟②： レビュー単位ごとの名称やID （例：対象機能ID、サブシステム名称） ∟③： レビュー方式 ∟④： レビュー回数 （2桁表記、"01"～"99"） （例） ED-共通-会議-02 （外部設計フェーズ、共通機能を対象とした会議レビューの2回目） | Q19: レビュー単位で、一意になるように決定する。
D20: レビュー方式 | M20: レビュー方法を、リストから選択する。 ・個人 … 各自机上で行うレビュー ・会議 … ミーティング形式のレビュー ・組織 … プロジェクト外（またはＧｒ外）のDCS社員が参加するレビュー ・顧客 … 顧客により成果物の妥当性を検証するレビュー | Q20: 詳細な定義は、「レビュープロセスガイドライン」を参照。
D21: アーキテクチャ | M21: レビュー対象となるプロジェクトのアーキテクチャを、リストから選択する。 ・ホスト ・C/S ・Web ・PROSRV ・基盤構築・更改 ・その他
D22: レビューの観点 | M22: レビューを実施する狙いは何か、何のためのレビューなのか（レビューの目的）を、記入する。 【標準的な観点】 ・設計の妥当性を検証する。 ・資料間の不整合がないか、確認する。 ・誤字脱字、形式不備を確認する。 ・仕様変更の取込漏れが無いかを確認する。 | Q22: レビューアは、レビューを実施する前に必要とされる観点が何かを一読すること。 また、フェーズ毎に観点を見直し、適切な観点でレビューが実施できるようにすること。
D23: 汎用カテゴリ | M23: 「レビュー状況分析表」による分析時に、レビューデータをカテゴリ分けするためのキー項目として、任意のキーワードを設定する。 | Q23: 例）サブシステム名、機能名、規模尺度など
D24: 役割 | M24: レビューに参加した担当者の役割を、リストから選択する。 役割を変更する場合は、以下表の項目を修正すること。
N25: 役割（リスト定義）
N26: レビューリーダー
N27: レビューア
N28: レビューア（有識者）
N29: レビューア（上位管理層）
N30: レビューア（関連業務有識者）
N31: PM
N32: 記録係
N33: 作業成果物作成者
N34: 欠陥管理者
D37: レビュー時間 | M37: 担当者毎にレビューを行った時間を記入する。 【記入単位】 ・分単位で記入する。 ・レビュー前の準備時間、検証時間、レビュー中の休憩時間は含めない。 例）ミーティング時間=1時間、参加者=3人のミーティング形式（会議、組織、顧客）で実施した場合、各担当者毎に「60分」を記録し、合計は3.0時間（時間換算）となる。 | Q37: レビュー効率を算出するために使用。 レビュー効率＝欠陥数÷レビュー時間
D38: レビュー時間密度 | M38: レビュー完了までの工数に占める、レビュー時間。「レビュー時間」と「作成工数」から自動算出する。 レビュー時間密度＝レビュー時間/（レビュー時間＋作成工数）
D39: 状態 | M39: レビューの管理状態を、レビュー指摘リストの記録内容から自動判定する。 ・CLOSE … 指摘無し、または、全ての指摘がクローズされており、レビュープロセスが終了している。 ・OPEN … クローズされていない指摘があり、レビュープロセスが終了していない。 | Q39: 指摘のクローズ条件は、「検証」項目を参照。
D40: 対象作業成果物 | M40: レビュー対象成果物名を記入する。 | Q40: レビュー指摘リストのファイル名は、ここで指定した対象作業成果物の一覧から選択することになる。 フォルダー内の複数のファイル名を取得する場合は、DOSコマンドを利用すると便利である。 例：コマンドプロンプト画面より「dir /b >a.txt」などを実行する。
D41: 作成工数 | M41: レビュー対象成果物の作成に要した工数を記入する。 既存成果物の修正部分のレビューの場合には、修正に要した工数のみを記入する。 【記入単位】 ・時間単位で記入する。 ・分は小数点第一位で表現する。 ・指摘対応時の工数（是正工数）は含めない。 | Q41: レビュー時間密度を算出するために使用。
D42: 【レビュー指摘リスト】
D43: 指摘 | M43: レビューで発見した指摘の内容を、レビューアが記入する。 | Q43: 【指摘属性の更新について】 ①指摘時に指摘者の判断で記入する。 ②対応検討時に見直して上書き修正する。
E44: 指摘分類 | M44: 指摘内容の分類をリストから選択する。分類名と選択肢は、「指摘分類（不備、改善、質問・確認）を初期値とする。プロジェクトに合わせて変更する場合は、以下の表を修正すること。 【例】 重要度（高・中・低）、緊急度（高・中・低）、優先度（高・中・低）
N45: 分類名
...

Sheet レビュー実施記録
A2: レビュー実施記録 | H2: （赤字の"*"が記述してある項目は必須入力項目です）
A4: プロジェクト名* | C4: SIEM導入
A5: レビューID * | D5: 実施フェーズ* | H5: 外部設計
A6: レビュー方式* | C6: 個人 | D6: アーキテクチャ | L6: 横展開調査欄の使用有無* | N6: 使用しない
A8: ◆レビューの観点 | L8: ◆指摘対応進捗 | V8: ◆横展開調査進捗
A9: No | B9: 観点 | N9: 総数 | X9: 総数
A10: 1 | B10: 設計の妥当性を検証する。 | L10: 指摘数 | N10: =COUNTA($I43:$I134) -> 76 | V10: 横展開調査数 | X10: =COUNTA($V43:$V134) -> 0
A11: 2 | B11: 資料間の不整合がないか、確認する。 | M11: 対応数 | N11: =SUM((COUNTIF($L43:$L134,"対応済み")),COUNTIF($L43:$L134,"対応無し")) -> 0 | W11: 調査「否」 | X11: =SUM((COUNTIF($V43:$V134,"否"))) -> 0
A12: 3 | B12: 誤字脱字、形式不備を確認する。 | M12: 保留数 | N12: =COUNTIF($L43:$L134,"保留") -> 0 | W12: 調査不要理由 入力済数 | X12: =COUNTA($W43:$W134) -> 0
A13: 4 | B13: 仕様変更の取込漏れが無いかを確認する。 | M13: 対応残数 | N13: =SUMPRODUCT((I43:I134<>"")*(L43:L134="保留")*(P43:P134=""))+SUMPRODUCT((I43:I134<>"")*(L43:L134="")) -> 76 | W13: 調査「要」 | X13: =SUM((COUNTIF($V43:$V134,"要"))) -> 0
A14: 5 | M14: 検証残数 | N14: =N10-(COUNTA($Q43:$Q134)) -> 76 | W14: 対応内容 入力済数 | X14: =COUNTA($Y43:$Y134) -> 0
A15: 6 | L15: レビュー時間密度 | N15: =IF(D38+N38<>0, ROUND(D38/(D38+N38),3), "-") -> 1 | V15: 対応残数 | X15: =X10-COUNTA($Z43:$Z134) -> 0
A16: 7 | L16: 状態 | N16: =レビューデータサマリ!F15 -> OPEN | V16: レビュー残数 | X16: =X10-COUNTA($AB43:$AB134) -> 0
V17: 状態（横展開） | X17: =IF(AND(X11=X12,X13=X14,X10=N10,X16=0,X15=0),"CLOSE","OPEN") -> OPEN
A18: ◆汎用カテゴリ （レビューデータを集計／分析する際にプロジェクト固有のカテゴリで分類したい場合に利用する） | L18: ◆レビューの参考資料（インプット資料、作業成果物との突き合わせ確認資料等）
A19: No | B19: 内容 | L19: 資料名
A20: 1
A21: 2
A22: 3
A24: ◆計画および実績 | L24: ◆レビュー対象成果物
A25: 実施日 | C25: 46296 | D25: 完了日 | H25: 46296 | I25: ※指摘0件の場合、左記欄に直接日付を記入してください。 | L25: 成果物種類*
A26: No | B26: 担当者 * | D26: レビュー時間（分）* | H26: 役割 | I26: 補足・コメント | L26: No | M26: 対象作業成果物* | N26: 作成工数 （時間）*
A28: 1 | B28: 下田 | D28: 150 | L28: 1 | M28: 【修正中】運用設計書_SIEM導入PoC_v1.1 1.xlsx
A29: 2 | L29: 2
A30: 3 | L30: 3
A31: 4 | L31: 4
A32: 5 | L32: 5
A33: 6 | L33: 6
A34: 7 | L34: 7
A35: 8 | L35: 8
A36: 9 | L36: 9
A37: 10 | L37: 10
A38: 合計 | C38: =COUNTA(B27:B37) -> 1 | D38: =SUM(D28:D37)/60 -> 2.5 | N38: =SUM(N27:N37) -> 0
A40: ◆レビュー指摘リスト | V40: ◆横展開調査（この欄を使用する場合、全ての指摘対応と横展開対応が検証済みになった場合、レビュー実施記録の状態欄が「CLOSE」となる）
B41: 指摘 | L41: 対応 | Q41: 検証 | S41: 顧客検証欄 | V41: 調査 要否 | W41: 調査「否」 | X41: 調査「要」 | Z41: 横展開 対応日 | AA41: 横展開 対応者 | AB41: 検証（横展開）
A42: No | B42: =使用方法!$N$46 -> 指摘分類 | C42: 原因区分* | D42: 指摘箇所 （ファイル名）* | E42: 章 | F42: 節 | G42: 項 | H42: 行番号等 | I42: 指摘内容* | J42: 指摘日* | K42: 指摘者* | L42: 対応状況* | M42: 対応内容* | N42: 対応日* | O42: 対応者* | P42: 関連ID | Q42: 検証日* | R42: 検証者* | S42: 顧客 検証日 | T42: 顧客 検証者 | W42: 理由 | X42: 調査の観点 | Y42: 対応内容 | AB42: 検証日 | AC42: 検証者
A43: =ROW()-ROW($A$42) -> 1 | B43: 改善 | C43: あいまい表現 | D43: 【修正中】運用設計書_SIEM導入PoC_v1.1 1.xlsx | H43: 全体 | I43: 表記ゆれ「通報」「通知」「一時連絡」が混在しているので、言葉を統一すること | J43: 46296 | K43: 下田
A44: =ROW()-ROW($A$42) -> 2 | B44: 改善 | C44: 仕様改善提案 | D44: 【修正中】運用設計書_SIEM導入PoC_v1.1 1.xlsx | H44: 全体 | I44: ナレッジツールとは何か？言葉の定義が不明 1.4の用語に記載する？ | J44: 46296 | K44: 下田
A45: =ROW()-ROW($A$42) -> 3 | B45: 改善 | C45: 仕様改善提案 | D45: 【修正中】運用設計書_SIEM導入PoC_v1.1 1.xlsx | H45: タイトル | I45: SIEM導入はプロジェクト名なので、「SIEM 運用設計書」とした方が良い | J45: 46296 | K45: 下田
A46: =ROW()-ROW($A$42) -> 4 | B46: 不備 | C46: 誤字脱字・形式不備 | D46: 【修正中】運用設計書_SIEM導入PoC_v1.1 1.xlsx | H46: ファイル名 | I46: PoCは要らないかと思います。 | J46: 46296 | K46: 下田
...

Sheet レビュー観点
A2: 開発工程成果物作成時／レビュー実施時の確認ポイント
A3: ※プロジェクトの特性に合わせて、チェック項目の内容は適宜修正すること。
A5: No | B5: 分類 | C5: チェック項目 | E5: 採用 | F5: 備考（未採用理由等）
A6: =ROW()-ROW($A$5) -> 1 | B6: 要件定義書 | C6: 開発の目的が明確になっているか。
A7: =ROW()-ROW($A$5) -> 2 | C7: 出力結果・還元物として、どういう内容が必要なのか明確になっているか。
A8: =ROW()-ROW($A$5) -> 3 | C8: 出力結果を得るために必要な入力情報が明確になっているか。
A9: =ROW()-ROW($A$5) -> 4 | C9: 全体のシステム構成が明確になっているか。（本番環境、準本番環境、開発環境など複数環境の差異が明確に記載されているか。）
A10: =ROW()-ROW($A$5) -> 5 | C10: 全体の運用イメージが明確になっているか。
A11: =ROW()-ROW($A$5) -> 6 | C11: お客様の要求事項が漏れなく取り込まれているか。
A12: =ROW()-ROW($A$5) -> 7 | B12: 外部設計書（全体） | C12: 実行条件毎の処理の流れが正しいか。
A13: =ROW()-ROW($A$5) -> 8 | C13: 機能間の連動（実行タイミング、データの授受）が正しいか。
A14: =ROW()-ROW($A$5) -> 9 | C14: データ項目名の意味は、各所で整合性が取れているか。
A15: =ROW()-ROW($A$5) -> 10 | C15: 要件が漏れなく外部設計に落とし込まれているか。
A16: =ROW()-ROW($A$5) -> 11 | B16: 外部設計書（機能設計） | C16: ジョブネットフローや処理機能フロー等を用いて、各モジュールの配置・処理の流れが明確になっているか。
A17: =ROW()-ROW($A$5) -> 12 | C17: 機能間の連動（実行タイミング、データの授受）が明確になっているか。
A18: =ROW()-ROW($A$5) -> 13 | C18: 対応機能の先行／後続機能に問題はないか。
A19: =ROW()-ROW($A$5) -> 14 | C19: 影響調査・範囲の観点 | D19: プログラムスキャン結果の確認に問題はないか。
A20: =ROW()-ROW($A$5) -> 15 | D20: 他業務のインタフェースに影響はあるか。（影響がある場合）他業務とのレビューは実施出来ているか。
A21: =ROW()-ROW($A$5) -> 16 | C21: 移行／切替、テスト方針の観点 | D21: 移行／切替ファイルは存在するか。（存在する場合）対象ファイルの洗い出し、一覧等で明示化され把握出来ているか。
A22: =ROW()-ROW($A$5) -> 17 | D22: 処理断面の確認が必要な対応か。 （繰り回しテストを実施する必要があるか、テスト方針の確認）
A23: =ROW()-ROW($A$5) -> 18 | D23: 大量データでのボリュームテストの要否を確認しているか。 （例：1日分の件数にて、テストを実施する必要があるかの確認）
A24: =ROW()-ROW($A$5) -> 19 | C24: 事前処理を行う場合の確認の観点 | D24: 事前処理の計画書を作成しているか。
A25: =ROW()-ROW($A$5) -> 20 | D25: 事前処理の目的に対して必要な確認ポイントが抜け漏れていないか。
A26: =ROW()-ROW($A$5) -> 21 | D26: 事前処理にて問題発生時の対処方法が明確になっているか。 （問題解決に対するスケジュール・要員等について取り決めが出来ているか。）
A27: =ROW()-ROW($A$5) -> 22 | C27: 本番確認の観点 | D27: 他業務に確認を依頼すべき事項はあるか。
A28: =ROW()-ROW($A$5) -> 23 | D28: 開発環境との差異による考慮事項を明確にし、説明が記述されているか。
A29: =ROW()-ROW($A$5) -> 24 | B29: モジュール設計書 | C29: ロジックをイメージして記述されているか。（但し、ロジックをそのまま記載するのはNG）
A30: =ROW()-ROW($A$5) -> 25 | C30: モジュールの処理シーケンスが正しいか。 （プログラム定義書上のシーケンスと設計書内の記載に整合性が取れているか）
A31: =ROW()-ROW($A$5) -> 26 | C31: データ項目名の意味は、各所で整合性が取れているか。
A32: =ROW()-ROW($A$5) -> 27 | C32: モジュール間での実行タイミング、データの授受が正しいか。
A33: =ROW()-ROW($A$5) -> 28 | C33: ファイル、データベースの更新、参照関係、シーケンスの整合性が取れているか。
A34: =ROW()-ROW($A$5) -> 29 | C34: 共通サブルーチンにより、共通化が図られているか。
A35: =ROW()-ROW($A$5) -> 30 | C35: プログラムの観点 | D35: 保守性：プログラム修正が容易な構造になっているか。
A36: =ROW()-ROW($A$5) -> 31 | D36: 拡張性：プログラムへの機能追加が容易な構造になっているか。
A37: =ROW()-ROW($A$5) -> 32 | D37: 簡潔性：プログラムは見易いか、構造は妥当か、ステップは大きすぎないか。
A38: =ROW()-ROW($A$5) -> 33 | C38: プログラムの目的が明確になっているか。目的を実現する為の設計仕様が明確になっているか。
A39: =ROW()-ROW($A$5) -> 34 | C39: プログラム定義書は作成されているか。
A40: =ROW()-ROW($A$5) -> 35 | C40: 変更内容の観点 | D40: 変更前の仕様、変更後の目的と仕様が明確になっているか。
A41: =ROW()-ROW($A$5) -> 36 | C41: 入力、処理、出力内容の観点 | D41: 入力データ（処理対象）に漏れはないか。
A42: =ROW()-ROW($A$5) -> 37 | D42: 抽象的な表現になっていないか。 （例：各種データ、全てのデータ等→具体的なデータ名で記載）
...

Sheet レビューデータサマリ
B2: レビューデータサマリ
C4: フェーズ順序定義 | F4: 順序
C5: 提案 | F5: 1
C6: 要件定義 | F6: 2
C7: 外部設計 | F7: 3
C8: 内部設計 | F8: 4
C9: プログラム開発 | F9: 5
C10: 結合テスト（ITa） | F10: 6
C11: 結合テスト（ITb） | F11: 7
C12: システムテスト | F12: 8
J13: 状態欄判定用
C14: レビューデータ | F14: 測定値 | G14: 単位 | H14: 尺度 | J14: ◆指摘対応進捗のみ | L14: {=IF(F31=SUMPRODUCT((レビュー実施記録!I43:I170<>"")*(レビュー実施記録!L43:L170="対応無し")*(レビュー実施記録!M43:M170<>"")*(レビュー実施記録!Q43:Q170<>"")*(レビュー実施記録!R43:R170<>""))+SUMPRODUCT((レビュー実施記録!I43:I170<>"")*(レビュー実施記録!L43:L170="対応済み")*(レビュー実施記録!M43:M170<>"")*(レビュー実施記録!Q43:Q170<>"")*(レビュー実施記録!R43:R170<>""))+SUMPRODUCT((レビュー実施記録!I43:I170<>"")*(レビュー実施記録!L43:L170="保留")*(レビュー実施記録!M43:M170<>"")*(レビュー実施記録!Q43:Q170<>"")*(レビュー実施記録!P43:P170<>"")*(レビュー実施記録!R43:R170<>"")),"CLOSE","OPEN")} -> OPEN
B15: 1 | C15: 状態 | F15: =IF(レビュー実施記録!N6="使用しない",レビューデータサマリ!L14,レビューデータサマリ!L15) -> OPEN | H15: CLOSE：指摘無し、または、全ての指摘がクローズされており、レビュープロセスが終了している。 OPEN：クローズされていない指摘があり、レビュープロセスが終了していない。 指摘のクローズ条件は使用方法シート参照。 | J15: ◆横展開進捗含む | L15: {=IF(AND(F31=SUMPRODUCT((レビュー実施記録!I43:I200<>"")*(レビュー実施記録!L43:L200="対応無し")*(レビュー実施記録!M43:M200<>"")*(レビュー実施記録!Q43:Q200<>"")*(レビュー実施記録!R43:R200<>""))+SUMPRODUCT((レビュー実施記録!I43:I200<>"")*(レビュー実施記録!L43:L200="対応済み")*(レビュー実施記録!M43:M200<>"")*(レビュー実施記録!Q43:Q200<>"")*(レビュー実施記録!R43:R200<>""))+SUMPRODUCT((レビュー実施記録!I43:I200<>"")*(レビュー実施記録!L43:L200="保留")*(レビュー実施記録!M43:M200<>"")*(レビュー実施記録!Q43:Q200<>"")*(レビュー実施記録!P43:P200<>"")*(レビュー実施記録!R43:R200<>"")),レビュー実施記録!X10=レビュー実施記録!N10,レビュー実施記録!X11=レビュー実施記録!X12,レビュー実施記録!X13=レビュー実施記録!X14,レビュー実施記録!X15=0,レビュー実施記録!X16=0),"CLOSE","OPEN")} -> OPEN
B16: 2 | C16: レビューID | F16: =IF(レビュー実施記録!C5="","-",レビュー実施記録!C5) -> - | H16: -
B17: 3 | C17: 実施フェーズ | F17: =IF(レビュー実施記録!H5="","-",レビュー実施記録!H5) -> 外部設計 | H17: -
B18: 4 | D18: （フェーズ順序） | F18: =IF(ISNA(VLOOKUP(F17,$C$5:$F$12,4,FALSE)),"-",VLOOKUP(F17,$C$5:$F$12,4,FALSE)) -> 3 | H18: 1:提案 2:要件定義 3:外部設計 4:内部設計 5:プログラム開発 6:結合テスト（ITa） 7:結合テスト（ITb） 8:システムテスト
B19: 5 | C19: レビュー方式 | F19: =IF(レビュー実施記録!C6="","-",レビュー実施記録!C6) -> 個人
B20: 6 | C20: アーキテクチャ | F20: =IF(レビュー実施記録!H6="","-",レビュー実施記録!H6) -> - | H20: -
B21: 7 | C21: 汎用カテゴリ1 | F21: =レビュー実施記録!B20 -> 0
B22: 8 | C22: 汎用カテゴリ2 | F22: =レビュー実施記録!B21 -> 0
B23: 9 | C23: 汎用カテゴリ3 | F23: =レビュー実施記録!B22 -> 0
B24: 10 | C24: 実施日 | F24: =IF(レビュー実施記録!C25="","-",レビュー実施記録!C25) -> 46296 | G24: yyyy/m/d | H24: レビュー開始日。
B25: 11 | C25: 完了日 | F25: =IF(レビュー実施記録!H25="","-",レビュー実施記録!H25) -> 46296 | G25: yyyy/m/d | H25: 検証完了日。
B26: 12 | C26: 成果物種類 | F26: =IF(レビュー実施記録!M25="","-",レビュー実施記録!M25) -> - | H26: -
B27: 13 | C27: 対象作業成果物 | F27: =レビュー実施記録!M28&IF(レビュー実施記録!M29="","",CHAR(10)&レビュー実施記録!M29)&IF(レビュー実施記録!M30="","",CHAR(10)&レビュー実施記録!M30)&IF(レビュー実施記録!M31="","",CHAR(10)&レビュー実施記録!M31)&IF(レビュー実施記録!M32="","",CHAR(10)&レビュー実施記録!M32)&IF(レビュー実施記録!M33="","",CHAR(10)&レビュー実施記録!M33)&IF(レビュー実施記録!M34="","",CHAR(10)&レビュー実施記録!M34)&IF(レビュー実施記録!M35="","",CHAR(10)&レビュー実施記録!M35)&IF(レビュー実施記録!M36="","",CHAR(10)&レビュー実施記録!M36)&IF(レビュー実施記録!M37="","",CHAR(10)&レビュー実施記録!M37) -> 【修正中】運用設計書_SIEM導入PoC_v1.1 1.xlsx | H27: -
B28: 14 | C28: 成果物作成工数 | F28: =IF(レビュー実施記録!N38="","-",レビュー実施記録!N38) -> 0 | G28: 時間 | H28: レビュー対象成果物の総作成工数。
B29: 15 | C29: レビューア人数 | F29: =IF(レビュー実施記録!C38="","-",レビュー実施記録!C38) -> 1 | G29: 人 | H29: レビュー担当者総数。
B30: 16 | C30: レビュー時間 | F30: =IF(レビュー実施記録!D38="","-",レビュー実施記録!D38) -> 2.5 | G30: 時間
B31: 17 | C31: 総指摘件数 | F31: =レビュー実施記録!N10 -> 76 | G31: 件
B32: 18 | D32: 総欠陥数 | F32: =SUM(F33:F39) -> 35 | G32: 件 | H32: 元資料不備、仕様取込不備、技術的不備、あいまい表現、考慮不足、不整合、ルール不順守の合計。
B33: 19 | D33: 元資料不備 | E33: 元資料不備 | F33: =COUNTIF(レビュー実施記録!C$43:C$134,レビューデータサマリ!D33) -> 0 | G33: 件
B34: 20 | D34: 仕様取込不備 | E34: 仕様取込不備 | F34: =COUNTIF(レビュー実施記録!C$43:C$134,レビューデータサマリ!D34) -> 0 | G34: 件
B35: 21 | D35: 技術的不備 | E35: 技術的不備 | F35: =COUNTIF(レビュー実施記録!C$43:C$134,レビューデータサマリ!D35) -> 0 | G35: 件
B36: 22 | D36: あいまい表現 | E36: あいまい表現 | F36: =COUNTIF(レビュー実施記録!C$43:C$134,レビューデータサマリ!D36) -> 9 | G36: 件
B37: 23 | D37: 考慮不足 | E37: 考慮不足 | F37: =COUNTIF(レビュー実施記録!C$43:C$134,レビューデータサマリ!D37) -> 11 | G37: 件
B38: 24 | D38: 不整合 | E38: 不整合 | F38: =COUNTIF(レビュー実施記録!C$43:C$134,レビューデータサマリ!D38) -> 15 | G38: 件
B39: 25 | D39: ルール不順守 | E39: ルール不順守 | F39: =COUNTIF(レビュー実施記録!C$43:C$134,レビューデータサマリ!D39) -> 0 | G39: 件
B40: 26 | D40: 誤字脱字・形式不備 | F40: =COUNTIF(レビュー実施記録!C$43:C$134,レビューデータサマリ!D40) -> 7 | G40: 件
B41: 27 | D41: 仕様改善提案 | F41: =COUNTIF(レビュー実施記録!C$43:C$134,レビューデータサマリ!D41) -> 20 | G41: 件
B42: 28 | C42: 指摘対応進捗 | F42: =IF(ISERROR(F47/F43),0,F47/F43) -> 0 | G42: 0 | H42: 総指摘件数に対する検証件数 ｛検証数/指摘数｝
...
